Workbook

Sheet 7. SED2014
M1: CLUSTER CLASSIFICATION
M2: No | N2: Cluster ID | O2: Prediction ID | P2: Prediction
B3: 3 -328.986671 43.336835 646.287913 -37.669330 -117.807540 43.540165 -9.720484 -161.585490 -77.402054 | C3: SUMMARY | M3: 1 | N3: 4970 | O3: =LEFT(B3,1) -> 3 | P3: =IF(O3="1","conference",IF(O3="2","fashion",IF(O3="3","concert",IF(O3="4","non_event",IF(O3="5","sport",IF(O3="6","protest",IF(O3="7","other",IF(O3="8","exhibition",IF(O3="9","theater_dance"))))))))) -> concert
B4: 3 -27.823130 -6.461752 41.963190 34.640887 -12.847042 -7.456983 -20.315716 -10.899685 9.199573 | C4: conference | D4: fashion | E4: concert | F4: non_event | G4: sports | H4: protest | I4: other | J4: exhibition | K4: theater_danc | M4: 2 | N4: 3640 | O4: =LEFT(B4,1) -> 3 | P4: =IF(O4="1","conference",IF(O4="2","fashion",IF(O4="3","concert",IF(O4="4","non_event",IF(O4="5","sport",IF(O4="6","protest",IF(O4="7","other",IF(O4="8","exhibition",IF(O4="9","theater_dance"))))))))) -> concert
A5: Pre ID | B5: 3 -657.004611 -156.094310 754.721951 278.562932 54.380057 0.874561 48.035578 -285.804843 -37.679240 | C5: 1 | D5: 2 | E5: 3 | F5: 4 | G5: 5 | H5: 6 | I5: 7 | J5: 8 | K5: 9 | M5: 3 | N5: 4971 | O5: =LEFT(B5,1) -> 3 | P5: =IF(O5="1","conference",IF(O5="2","fashion",IF(O5="3","concert",IF(O5="4","non_event",IF(O5="5","sport",IF(O5="6","protest",IF(O5="7","other",IF(O5="8","exhibition",IF(O5="9","theater_dance"))))))))) -> concert
A6: No_records | B6: 3 -708.995422 130.683629 877.193418 634.765177 -116.707348 -7.643512 -254.412557 -368.378230 -186.510817 | C6: =COUNTIF($P$3:$P$17836,C4) -> 0 | D6: =COUNTIF($P$3:$P$17836,D4) -> 0 | E6: =COUNTIF($P$3:$P$17836,E4) -> 13685 | F6: =COUNTIF($P$3:$P$17836,F4) -> 4003 | G6: =COUNTIF($P$3:$P$17836,G4) -> 0 | H6: =COUNTIF($P$3:$P$17836,H4) -> 12 | I6: =COUNTIF($P$3:$P$17836,I4) -> 10 | J6: =COUNTIF($P$3:$P$17836,J4) -> 5 | K6: =COUNTIF($P$3:$P$17836,K4) -> 0 | M6: 4 | N6: 2306 | O6: =LEFT(B6,1) -> 3 | P6: =IF(O6="1","conference",IF(O6="2","fashion",IF(O6="3","concert",IF(O6="4","non_event",IF(O6="5","sport",IF(O6="6","protest",IF(O6="7","other",IF(O6="8","exhibition",IF(O6="9","theater_dance"))))))))) -> concert
B7: 3 -13587.555443 1706.394689 25774.937909 18070.334643 -8497.698893 -1467.751441 -6380.830863 -8996.608915 -6621.338345 | M7: 5 | N7: 3638 | O7: =LEFT(B7,1) -> 3 | P7: =IF(O7="1","conference",IF(O7="2","fashion",IF(O7="3","concert",IF(O7="4","non_event",IF(O7="5","sport",IF(O7="6","protest",IF(O7="7","other",IF(O7="8","exhibition",IF(O7="9","theater_dance"))))))))) -> concert
B8: 3 -971.782396 -373.844771 2523.911295 1323.809082 -587.636550 -615.252068 -1238.258147 -1151.492651 1090.512330 | M8: 6 | N8: 4969 | O8: =LEFT(B8,1) -> 3 | P8: =IF(O8="1","conference",IF(O8="2","fashion",IF(O8="3","concert",IF(O8="4","non_event",IF(O8="5","sport",IF(O8="6","protest",IF(O8="7","other",IF(O8="8","exhibition",IF(O8="9","theater_dance"))))))))) -> concert
B9: 3 -1893.826683 87.008671 4278.938361 603.828506 -284.454970 -67.522159 -579.187207 -1189.722398 -955.075235 | M9: 7 | N9: 2305 | O9: =LEFT(B9,1) -> 3 | P9: =IF(O9="1","conference",IF(O9="2","fashion",IF(O9="3","concert",IF(O9="4","non_event",IF(O9="5","sport",IF(O9="6","protest",IF(O9="7","other",IF(O9="8","exhibition",IF(O9="9","theater_dance"))))))))) -> concert
B10: 3 -17266.735197 5.890476 36007.739745 22871.687752 -12734.904263 -11285.126078 1248.199903 -18986.966631 139.859478 | M10: 8 | N10: 3639 | O10: =LEFT(B10,1) -> 3 | P10: =IF(O10="1","conference",IF(O10="2","fashion",IF(O10="3","concert",IF(O10="4","non_event",IF(O10="5","sport",IF(O10="6","protest",IF(O10="7","other",IF(O10="8","exhibition",IF(O10="9","theater_dance"))))))))) -> concert
B11: 3 -188.508438 40.731100 197.917587 131.714194 -46.609749 18.542558 -11.369205 -109.567051 -32.853121 | M11: 9 | N11: 2304 | O11: =LEFT(B11,1) -> 3 | P11: =IF(O11="1","conference",IF(O11="2","fashion",IF(O11="3","concert",IF(O11="4","non_event",IF(O11="5","sport",IF(O11="6","protest",IF(O11="7","other",IF(O11="8","exhibition",IF(O11="9","theater_dance"))))))))) -> concert
B12: 4 -1728.766187 -58.079852 2566.494006 3040.057949 -1033.900612 592.556207 -1322.073120 -1137.815989 -918.482932 | M12: 10 | N12: 2302 | O12: =LEFT(B12,1) -> 4 | P12: =IF(O12="1","conference",IF(O12="2","fashion",IF(O12="3","concert",IF(O12="4","non_event",IF(O12="5","sport",IF(O12="6","protest",IF(O12="7","other",IF(O12="8","exhibition",IF(O12="9","theater_dance"))))))))) -> non_event
B13: 3 -1306.424864 216.769216 2269.304141 1923.400875 -825.290228 -79.616075 -477.878899 -1091.006760 -629.266888 | M13: 11 | N13: 2301 | O13: =LEFT(B13,1) -> 3 | P13: =IF(O13="1","conference",IF(O13="2","fashion",IF(O13="3","concert",IF(O13="4","non_event",IF(O13="5","sport",IF(O13="6","protest",IF(O13="7","other",IF(O13="8","exhibition",IF(O13="9","theater_dance"))))))))) -> concert
B14: 3 -1618.564010 21.806678 2463.597397 1229.988939 -401.794079 -231.045179 195.780893 -1322.785955 -337.003779 | M14: 12 | N14: 2300 | O14: =LEFT(B14,1) -> 3 | P14: =IF(O14="1","conference",IF(O14="2","fashion",IF(O14="3","concert",IF(O14="4","non_event",IF(O14="5","sport",IF(O14="6","protest",IF(O14="7","other",IF(O14="8","exhibition",IF(O14="9","theater_dance"))))))))) -> concert
B15: 4 -4580.784728 906.204382 6835.199617 7019.454927 -1627.977314 -1955.861455 -3631.147802 -3808.217876 843.048595 | M15: 13 | N15: 3630 | O15: =LEFT(B15,1) -> 4 | P15: =IF(O15="1","conference",IF(O15="2","fashion",IF(O15="3","concert",IF(O15="4","non_event",IF(O15="5","sport",IF(O15="6","protest",IF(O15="7","other",IF(O15="8","exhibition",IF(O15="9","theater_dance"))))))))) -> non_event
B16: 4 -1478.990046 252.637800 940.245056 2320.219602 -509.179084 -35.905910 -410.738009 -672.381070 -405.917862 | M16: 14 | N16: 4961 | O16: =LEFT(B16,1) -> 4 | P16: =IF(O16="1","conference",IF(O16="2","fashion",IF(O16="3","concert",IF(O16="4","non_event",IF(O16="5","sport",IF(O16="6","protest",IF(O16="7","other",IF(O16="8","exhibition",IF(O16="9","theater_dance"))))))))) -> non_event
B17: 3 -46.727528 -9.894183 85.921440 15.315540 -1.215969 -5.270792 -25.484044 -20.953517 8.308436 | M17: 15 | N17: 3631 | O17: =LEFT(B17,1) -> 3 | P17: =IF(O17="1","conference",IF(O17="2","fashion",IF(O17="3","concert",IF(O17="4","non_event",IF(O17="5","sport",IF(O17="6","protest",IF(O17="7","other",IF(O17="8","exhibition",IF(O17="9","theater_dance"))))))))) -> concert
B18: 4 -4253.210841 -77.791841 3714.865275 4065.109108 -384.423385 142.095877 -1332.040573 -1185.492059 -689.152430 | M18: 16 | N18: 4962 | O18: =LEFT(B18,1) -> 4 | P18: =IF(O18="1","conference",IF(O18="2","fashion",IF(O18="3","concert",IF(O18="4","non_event",IF(O18="5","sport",IF(O18="6","protest",IF(O18="7","other",IF(O18="8","exhibition",IF(O18="9","theater_dance"))))))))) -> non_event
... B17836: 4 -475.770031 85.551625 514.472751 592.442884 -231.507852 -45.351033 -96.344052 -211.079152 -132.418281 | M17836: 17834 | N17836: 4957 | O17836: =LEFT(B17836,1) -> 4 | P17836: =IF(O17836="1","conference",IF(O17836="2","fashion",IF(O17836="3","concert",IF(O17836="4","non_event",IF(O17836="5","sport",IF(O17836="6","protest",IF(O17836="7","other",IF(O17836="8","exhibition",IF(O17836="9","theater_dance"))))))))) -> non_event

Sheet 4. Cross-validation
A1: EXP- F1 CROSS VALIDATION - NO_IMBALANCE RESOLVE
A2: Details
A3: _Exp base | B3: Max=3 | C3: Limit=10 | D3: 1metric (LIN) | F3: No replacement (concatinate)
A4: _ c=2^15
A5: Column1 | B5: Fold 0 (w/t visual) | C5: Fold 1 (w/t visual) | D5: Fold 2 (w/t visual) | E5: Fold 3 (w/t visual) | F5: Fold 4 (w/t visual) | G5: Fold 5 (w/t visual) | H5: Fold 6 (w/t visual) | I5: Fold 7 (w/t visual) | J5: Fold 8 (w/t visual) | K5: Fold 9 (w/t visual) | L5: Baseline (w/t visual, resampled) | M5: Your method (with visual)
A6: conference | B6: 0.26666667 | C6: 0.4 | D6: 0.5 | E6: 0.33333333 | F6: 0.125 | G6: 0 | H6: 0.13333333 | I6: 0.44444444 | J6: 0 | K6: 0.26666667 | L6: 0.5137 | M6: 0.3271
A7: fashion | B7: 0 | C7: 0 | D7: 0.4 | E7: 0 | F7: 0 | G7: 0.8 | H7: 0 | I7: 0 | J7: 0 | K7: 0 | L7: 0.1764 | M7: 0.2857
A8: concert | B8: 0.56737589 | C8: 0.57758621 | D8: 0.57207207 | E8: 0.55684455 | F8: 0.56470588 | G8: 0.58571429 | H8: 0.52300242 | I8: 0.529274 | J8: 0.51798561 | K8: 0.5177665 | L8: 0.5264 | M8: 0.6023
A9: non_event | B9: 0.94601128 | C9: 0.94358766 | D9: 0.94411943 | E9: 0.94251012 | F9: 0.94003634 | G9: 0.94517499 | H9: 0.93890675 | I9: 0.94010889 | J9: 0.94049055 | K9: 0.93804238 | L9: 0.9229 | M9: 0.9462
A10: sports | B10: 0.2 | C10: 0.3 | D10: 0.3 | E10: 0.1 | F10: 0.12903226 | G10: 0.21428571 | H10: 0.08 | I10: 0.23076923 | J10: 0.16666667 | K10: 0.21052632 | L10: 0.1495 | M10: 0.1803
A11: protest | B11: 0.58333333 | C11: 0.69565217 | D11: 0.75 | E11: 0.81081081 | F11: 0.77419355 | G11: 0.8125 | H11: 0.73684211 | I11: 0.75 | J11: 0.48 | K11: 0.68421053 | L11: 0.6457 | M11: 0.7152
A12: other | B12: 0.11764706 | C12: 0.10526316 | D12: 0.1 | E12: 0.083333333 | F12: 0.066666667 | G12: 0 | H12: 0.11764706 | I12: 0.2 | J12: 0 | K12: 0.11764706 | L12: 0.1119 | M12: 0.1527
A13: exhibition | B13: 0.27272727 | C13: 0.23809524 | D13: 0.068965517 | E13: 0.25 | F13: 0.12903226 | G13: 0.15384615 | H13: 0.11428571 | I13: 0.11111111 | J13: 0.19354839 | K13: 0.14285714 | L13: 0.215 | M13: 0.1928
A14: theater_dance | B14: 0.58823529 | C14: 0.74285714 | D14: 0.55172414 | E14: 0.68181818 | F14: 0.4137931 | G14: 0.80851064 | H14: 0.4 | I14: 0.47619048 | J14: 0.6 | K14: 0.71111111 | L14: 0.4 | M14: 0.5722
A15: AVERAGE | B15: =AVERAGE(B6:B14) -> 0.3935552 | C15: =AVERAGE(C6:C14) -> 0.4447824 | D15: =AVERAGE(D6:D14) -> 0.46520902 | E15: =AVERAGE(E6:E14) -> 0.41762781 | F15: =AVERAGE(F6:F14) -> 0.34916223 | G15: =AVERAGE(G6:G14) -> 0.48000353 | H15: =AVERAGE(H6:H14) -> 0.33822415 | I15: =AVERAGE(I6:I14) -> 0.4090998 | ... M15: =AVERAGE(M6:M14) -> 0.44161111
A19: Base- F1 CROSS VALIDATION - NO_IMBALANCE RESOLVE
A20: Details
A21: _Baseline
A22: _ c=2^15
A23: Column1 | B23: Fold 0 (w/t visual) | C23: Fold 1 (w/t visual) | D23: Fold 2 (w/t visual) | E23: Fold 3 (w/t visual) | F23: Fold 4 (w/t visual) | G23: Fold 5 (w/t visual) | H23: Fold 6 (w/t visual) | I23: Fold 7 (w/t visual) | J23: Fold 8 (w/t visual) | K23: Fold 9 (w/t visual)
A24: conference | B24: 0 | C24: 0 | D24: 0 | E24: 0 | F24: 0 | G24: 0 | H24: 0 | I24: 0 | J24: 0 | K24: 0
A25: fashion | B25: 0 | C25: 0 | D25: 0 | E25: 0 | F25: 0 | G25: 0 | H25: 0 | I25: 0 | J25: 0 | K25: 0
A26: concert | B26: 0.076576577 | C26: 0.053789731 | D26: 0.089686099 | E26: 0.066666667 | F26: 0.050343249 | G26: 0.087356322 | H26: 0.049627792 | I26: 0.063882064 | J26: 0.082125604 | K26: 0.087759815
A27: non_event | B27: 0.89090909 | C27: 0.89148379 | D27: 0.88649746 | E27: 0.89400363 | F27: 0.886953 | G27: 0.89488522 | H27: 0.89464178 | I27: 0.89455714 | J27: 0.89364279 | K27: 0.89457771
A28: sports | B28: 0 | C28: 0 | D28: 0 | E28: 0 | F28: 0 | G28: 0 | H28: 0 | I28: 0 | J28: 0 | K28: 0
A29: protest | B29: 0 | C29: 0 | D29: 0 | E29: 0 | F29: 0 | G29: 0 | H29: 0 | I29: 0 | J29: 0 | K29: 0
A30: other | B30: 0 | C30: 0 | D30: 0 | E30: 0 | F30: 0 | G30: 0 | H30: 0 | I30: 0 | J30: 0 | K30: 0
A31: exhibition | B31: 0.0625 | C31: 0 | D31: 0 | E31: 0 | F31: 0 | G31: 0 | H31: 0 | I31: 0.076923077 | J31: 0 | K31: 0
A32: theater_dance | B32: 0 | C32: 0 | D32: 0.057142857 | E32: 0 | F32: 0 | G32: 0 | H32: 0 | I32: 0 | J32: 0 | K32: 0
A33: AVERAGE | B33: =AVERAGE(B24:B32) -> 0.11444285 | C33: =AVERAGE(C24:C32) -> 0.10503039 | D33: =AVERAGE(D24:D32) -> 0.11481405 | E33: =AVERAGE(E24:E32) -> 0.10674114 | F33: =AVERAGE(F24:F32) -> 0.10414403 | G33: =AVERAGE(G24:G32) -> 0.10913795 | H33: =AVERAGE(H24:H32) -> 0.10491884 | I33: =AVERAGE(I24:I32) -> 0.11504025 | ... K33: =AVERAGE(K24:K32) -> 0.10914861
I35: =AVERAGE(B33:K33) -> 0.10918368
A38: Base- F1 CROSS VALIDATION - NO_IMBALANCE RESOLVE
A39: Details
A40: _Baseline
A41: _ c=130,000
A42: Column1 | B42: Fold 0 (w/t visual) | C42: Fold 1 (w/t visual) | D42: Fold 2 (w/t visual) | E42: Fold 3 (w/t visual) | F42: Fold 4 (w/t visual) | G42: Fold 5 (w/t visual) | H42: Fold 6 (w/t visual) | I42: Fold 7 (w/t visual) | J42: Fold 8 (w/t visual) | K42: Fold 9 (w/t visual)
A43: conference | B43: 0 | C43: 0 | D43: 0 | E43: 0 | F43: 0 | G43: 0 | H43: 0 | I43: 0 | J43: 0 | K43: 0
A44: fashion | B44: 0 | C44: 0 | D44: 0 | E44: 0 | F44: 0 | G44: 0 | H44: 0 | I44: 0 | J44: 0 | K44: 0
A45: concert | B45: 0.066964286 | C45: 0.10278373 | D45: 0.055555556 | E45: 0.074074074 | F45: 0.08137045 | G45: 0.063965885 | H45: 0.069868996 | I45: 0.079254079 | J45: 0.10191083 | K45: 0.082608696
A46: non_event | B46: 0.88409923 | C46: 0.88258117 | D46: 0.88208894 | E46: 0.88603989 | F46: 0.88109321 | G46: 0.87944422 | H46: 0.88204082 | I46: 0.89180991 | J46: 0.88256956 | K46: 0.88150112
...

Sheet 5. ReCrossValidation
A1: OBJECTIVE | E1: DO
A2: Prepare for ACIS | E2: Cross-validation in training set with and without YAGO enrichment
A4: Params
A5: _Linear
A6: _c=2^15
A8: WITH YAGO ENRICHMENT CLASSIFICATION RESULT
A9: _Measure: Lin | C9: _ Concatinate
A10: _Result limit: 10 | C10: _Link: virtual computer 3\ C:\PERSONAL_FILES\ForACIS2014\
A11: _Maxresult: 3
A12: Event | B12: Fold0 | C12: Fold1 | D12: Fold2 | E12: Fold3 | F12: Fold4
A13: conference | B13: 0.4137931 | C13: 0.42857143 | D13: 0.38461538 | E13: 0.28571429 | F13: 0.16666667
A14: concert | B14: 0.55841121 | C14: 0.53623188 | D14: 0.57562077 | E14: 0.55284553 | F14: 0.52340936
A15: theater_dance | B15: 0.53333333 | C15: 0.69230769 | D15: 0.73846154 | E15: 0.62295082 | F15: 0.58333333
A16: sports | B16: 0.125 | C16: 0.23809524 | D16: 0.28571429 | E16: 0.15384615 | F16: 0.29508197
A17: protest | B17: 0.77142857 | C17: 0.65753425 | D17: 0.73913043 | E17: 0.725 | F17: 0.7755102
A18: other | B18: 0.13043478 | C18: 0 | D18: 0.095238095 | E18: 0.046511628 | F18: 0.125
A19: non_event | B19: 0.94122408 | C19: 0.94236195 | D19: 0.94419215 | E19: 0.94136676 | F19: 0.94054817
A20: fashion | B20: 0.33333333 | C20: 0 | D20: 0.2 | E20: 0 | F20: 0
A21: exhibition | B21: 0.16901408 | C21: 0.19354839 | D21: 0.14492754 | E21: 0.18461538 | F21: 0.23376623
A22: AVERAGE | B22: =AVERAGE(Table6[Fold0]) -> 0.44177472 | C22: =AVERAGE(Table6[Fold1]) -> 0.40985009 | D22: =AVERAGE(Table6[Fold2]) -> 0.45643335 | E22: =AVERAGE(Table6[Fold3]) -> 0.39031673 | F22: =AVERAGE(Table6[Fold4]) -> 0.40481288
E24: =AVERAGE(Table6[[#Totals],[Fold0]:[Fold4]]) -> 0.42063756
F26: RUN 0 | G26: Netbeans version
A27: WITHOUT YAGO ENRICHMENT CLASSIFICATION RESULT
A28: Event | B28: Fold0 | C28: Fold1 | D28: Fold2 | E28: Fold3 | F28: Fold4
A29: conference | B29: 0 | C29: 0 | D29: 0 | E29: 0 | F29: 0
A30: concert | B30: 0.07184241 | C30: 0.057736721 | D30: 0.070093458 | E30: 0.060535506 | F30: 0.077953715
A31: theater_dance | B31: 0 | C31: 0 | D31: 0 | E31: 0.03030303 | F31: 0
A32: sports | B32: 0 | C32: 0 | D32: 0 | E32: 0 | F32: 0
A33: protest | B33: 0 | C33: 0 | D33: 0 | E33: 0 | F33: 0
A34: other | B34: 0 | C34: 0 | D34: 0 | E34: 0 | F34: 0
A35: non_event | B35: 0.89202825 | C35: 0.88976458 | D35: 0.89079532 | E35: 0.88747217 | F35: 0.89459895
A36: fashion | B36: 0 | C36: 0 | D36: 0 | E36: 0 | F36: 0
A37: exhibition | B37: 0 | C37: 0 | D37: 0 | E37: 0 | F37: 0.085714286
A38: AVERAGE | B38: =AVERAGE(Table68[Fold0]) -> 0.10709674 | C38: =AVERAGE(Table68[Fold1]) -> 0.10527792 | D38: =AVERAGE(Table68[Fold2]) -> 0.10676542 | E38: =AVERAGE(Table68[Fold3]) -> 0.10870119 | F38: =AVERAGE(Table68[Fold4]) -> 0.11758522
F43: RUN 1 | G43: File Pick
A44: WITHOUT YAGO ENRICHMENT CLASSIFICATION RESULT
A45: Event | B45: Fold0 | C45: Fold1 | D45: Fold2 | E45: Fold3 | F45: Fold4
A46: conference | B46: 0 | C46: 0 | D46: 0 | E46: 0 | F46: 0
A47: concert | B47: 0.091928251 | C47: 0.070921986 | D47: 0.048667439 | E47: 0.069306931 | F47: 0.075170843
A48: theater_dance | B48: 0 | C48: 0 | D48: 0 | E48: 0.027027027 | F48: 0
...

Sheet 6. For thesis
A2: c | B2: 0.01 | C2: 1.00 | D2: 100.00 | E2: 500.00 | F2: 1,000.00 | G2: 2,000.00 | H2: 3,000.00 | I2: 5,000.00 | J2: 7,000.00 | K2: 10,000.00 | L2: 20,000.00 | M2: 32,768.00 | N2: 50,000.00 | O2: 100,000.00 | P2: 130,000.00 | Q2: 150,000.00 | R2: 200,000.00 | S2: 400,000.00 | T2: 700,000.00
A3: theater_dance | B3: 0 | C3: 0 | D3: 0 | E3: 2 | F3: 3 | G3: 10 | H3: 15 | I3: 27 | J3: 40 | K3: 52 | L3: 62 | N3: 57 | O3: 53 | P3: 56 | Q3: 53 | R3: 54 | S3: 55 | T3: 53
A4: theater_dance | B4: 29291 | C4: 29291 | D4: 29291 | E4: 29289 | F4: 29286 | G4: 29274 | H4: 29264 | I4: 29239 | J4: 29224 | K4: 29209 | L4: 29192 | N4: 29192 | O4: 29173 | P4: 29177 | Q4: 29173 | R4: 29172 | S4: 29183 | T4: 29188
A5: theater_dance | B5: 120 | C5: 120 | D5: 120 | E5: 118 | F5: 117 | G5: 110 | H5: 105 | I5: 93 | J5: 80 | K5: 68 | L5: 58 | N5: 63 | O5: 67 | P5: 64 | Q5: 67 | R5: 66 | S5: 65 | T5: 67
A6: theater_dance | B6: 0 | C6: 0 | D6: 0 | E6: 2 | F6: 5 | G6: 17 | H6: 27 | I6: 52 | J6: 67 | K6: 82 | L6: 99 | N6: 99 | O6: 118 | P6: 114 | Q6: 118 | R6: 119 | S6: 108 | T6: 103
A7: theater_dance | B7: 0 | C7: 0 | D7: 0 | E7: 0.016666667 | F7: 0.025 | G7: 0.083333333 | H7: 0.125 | I7: 0.225 | J7: 0.33333333 | K7: 0.43333333 | L7: 0.51666667 | N7: 0.475 | O7: 0.44166667 | P7: 0.46666667 | Q7: 0.44166667 | R7: 0.45 | S7: 0.45833333 | T7: 0.44166667
A8: theater_dance | B8: NaN | C8: NaN | D8: NaN | E8: 0.5 | F8: 0.375 | G8: 0.37037037 | H8: 0.35714286 | I8: 0.34177215 | J8: 0.37383178 | K8: 0.3880597 | L8: 0.38509317 | N8: 0.36538462 | O8: 0.30994152 | P8: 0.32941176 | Q8: 0.30994152 | R8: 0.31213873 | S8: 0.33742331 | T8: 0.33974359
A9: theater_dance | B9: 0 | C9: 0 | D9: 0 | E9: 0.032258065 | F9: 0.046875 | G9: 0.13605442 | H9: 0.18518519 | I9: 0.27135678 | J9: 0.35242291 | K9: 0.40944882 | L9: 0.44128114 | M9: 0.4 | N9: 0.41304348 | O9: 0.36426117 | P9: 0.3862069 | Q9: 0.36426117 | R9: 0.36860068 | S9: 0.38869258 | T9: 0.38405797
A10: theater_dance | B10: 0.99591989 | C10: 0.99591989 | D10: 0.99591989 | E10: 0.99591989 | F10: 0.99585189 | G10: 0.99568189 | H10: 0.99551188 | I10: 0.99506987 | J10: 0.99500187 | K10: 0.99489987 | L10: 0.99466186 | N10: 0.99449186 | O10: 0.99370984 | P10: 0.99394784 | Q10: 0.99370984 | R10: 0.99370984 | S10: 0.99411785 | T10: 0.99421985
A13: concert | B13: 0 | C13: 0 | D13: 0 | E13: 39 | F13: 127 | G13: 231 | H13: 287 | I13: 410 | J13: 481 | K13: 541 | L13: 625 | N13: 737 | O13: 825 | P13: 805 | Q13: 825 | R13: 800 | S13: 820 | T13: 781
A14: concert | B14: 27522 | C14: 27522 | D14: 27522 | E14: 27514 | F14: 27484 | G14: 27453 | H14: 27433 | I14: 27385 | J14: 27364 | K14: 27331 | L14: 27261 | N14: 27134 | O14: 26814 | P14: 26969 | Q14: 26814 | R14: 26915 | S14: 26848 | T14: 26794
A15: concert | B15: 1889 | C15: 1889 | D15: 1889 | E15: 1850 | F15: 1762 | G15: 1658 | H15: 1602 | I15: 1479 | J15: 1408 | K15: 1348 | L15: 1264 | N15: 1152 | O15: 1064 | P15: 1084 | Q15: 1064 | R15: 1089 | S15: 1069 | T15: 1108
A16: concert | B16: 0 | C16: 0 | D16: 0 | E16: 8 | F16: 38 | G16: 69 | H16: 89 | I16: 137 | J16: 158 | K16: 191 | L16: 261 | N16: 388 | O16: 708 | P16: 553 | Q16: 708 | R16: 607 | S16: 674 | T16: 728
A17: concert | B17: 0 | C17: 0 | D17: 0 | E17: 0.020645844 | F17: 0.067231339 | G17: 0.12228692 | H17: 0.15193224 | I17: 0.21704606 | J17: 0.25463208 | K17: 0.28639492 | L17: 0.33086289 | N17: 0.39015352 | O17: 0.43673902 | P17: 0.4261514 | Q17: 0.43673902 | R17: 0.4235045 | S17: 0.43409211 | T17: 0.41344627
A18: concert | B18: NaN | C18: NaN | D18: NaN | E18: 0.82978723 | F18: 0.76969697 | G18: 0.77 | H18: 0.76329787 | I18: 0.74954296 | J18: 0.75273865 | K18: 0.73907104 | L18: 0.70541761 | N18: 0.65511111 | O18: 0.53816047 | P18: 0.59278351 | Q18: 0.53816047 | R18: 0.56858564 | S18: 0.54886212 | T18: 0.5175613
A19: concert | B19: 0 | C19: 0 | D19: 0 | E19: 0.040289256 | F19: 0.12366115 | G19: 0.21105528 | H19: 0.25342163 | I19: 0.33661741 | J19: 0.38053797 | K19: 0.41281953 | L19: 0.45045045 | M19: 0.5264 | N19: 0.48905109 | O19: 0.48217417 | P19: 0.49584232 | Q19: 0.48217417 | R19: 0.48543689 | S19: 0.48477683 | T19: 0.45968217
A20: concert | B20: 0.93577233 | C20: 0.93577233 | D20: 0.93577233 | E20: 0.93682636 | F20: 0.93879841 | G20: 0.94128047 | H20: 0.94250451 | I20: 0.94505457 | J20: 0.94675462 | K20: 0.94767264 | L20: 0.94814865 | N20: 0.94763864 | O20: 0.93975043 | P20: 0.94434055 | Q20: 0.93975043 | R20: 0.9423345 | S20: 0.94073646 | T20: 0.93757438
A23: conference | B23: 0 | C23: 0 | D23: 0 | E23: 0 | F23: 0 | G23: 0 | H23: 0 | I23: 0 | J23: 0 | K23: 0 | L23: 2 | N23: 9 | O23: 12 | P23: 13 | Q23: 12 | R23: 12 | S23: 12 | T23: 11
A24: conference | B24: 29299 | C24: 29299 | D24: 29299 | E24: 29299 | F24: 29299 | G24: 29299 | H24: 29299 | I24: 29299 | J24: 29299 | K24: 29297 | L24: 29296 | N24: 29291 | O24: 29293 | P24: 29292 | Q24: 29293 | R24: 29293 | S24: 29293 | T24: 29289
A25: conference | B25: 112 | C25: 112 | D25: 112 | E25: 112 | F25: 112 | G25: 112 | H25: 112 | I25: 112 | J25: 112 | K25: 112 | L25: 110 | N25: 103 | O25: 100 | P25: 99 | Q25: 100 | R25: 100 | S25: 100 | T25: 101
A26: conference | B26: 0 | C26: 0 | D26: 0 | E26: 0 | F26: 0 | G26: 0 | H26: 0 | I26: 0 | J26: 0 | K26: 2 | L26: 3 | N26: 8 | O26: 6 | P26: 7 | Q26: 6 | R26: 6 | S26: 6 | T26: 10
A27: conference | B27: 0 | C27: 0 | D27: 0 | E27: 0 | F27: 0 | G27: 0 | H27: 0 | I27: 0 | J27: 0 | K27: 0 | L27: 0.017857143 | N27: 0.080357143 | O27: 0.10714286 | P27: 0.11607143 | Q27: 0.10714286 | R27: 0.10714286 | S27: 0.10714286 | T27: 0.098214286
A28: conference | B28: NaN | C28: NaN | D28: NaN | E28: NaN | F28: NaN | G28: NaN | H28: NaN | I28: NaN | J28: NaN | K28: 0 | L28: 0.4 | N28: 0.52941176 | O28: 0.66666667 | P28: 0.65 | Q28: 0.66666667 | R28: 0.66666667 | S28: 0.66666667 | T28: 0.52380952
A29: conference | B29: 0 | C29: 0 | D29: 0 | E29: 0 | F29: 0 | G29: 0 | H29: 0 | I29: 0 | J29: 0 | K29: 0 | L29: 0.034188034 | M29: 0.5137 | N29: 0.13953488 | O29: 0.18461538 | P29: 0.1969697 | Q29: 0.18461538 | R29: 0.18461538 | S29: 0.18461538 | T29: 0.16541353
A30: conference | B30: 0.9961919 | C30: 0.9961919 | D30: 0.9961919 | E30: 0.9961919 | F30: 0.9961919 | G30: 0.9961919 | H30: 0.9961919 | I30: 0.9961919 | J30: 0.9961919 | K30: 0.9961239 | L30: 0.9961579 | N30: 0.9962259 | O30: 0.99639591 | P30: 0.99639591 | Q30: 0.99639591 | R30: 0.99639591 | S30: 0.99639591 | T30: 0.9962259
A33: exhibition | B33: 0 | C33: 0 | D33: 0 | E33: 0 | F33: 0 | G33: 0 | H33: 0 | I33: 0 | J33: 0 | K33: 0 | L33: 0 | N33: 3 | O33: 27 | P33: 18 | Q33: 27 | R33: 27 | S33: 27 | T33: 22
A34: exhibition | B34: 29274 | C34: 29274 | D34: 29274 | E34: 29274 | F34: 29274 | G34: 29274 | H34: 29274 | I34: 29274 | J34: 29272 | K34: 29267 | L34: 29261 | N34: 29232 | O34: 29157 | P34: 29204 | Q34: 29157 | R34: 29194 | S34: 29176 | T34: 29144
A35: exhibition | B35: 137 | C35: 137 | D35: 137 | E35: 137 | F35: 137 | G35: 137 | H35: 137 | I35: 137 | J35: 137 | K35: 137 | L35: 137 | N35: 134 | O35: 110 | P35: 119 | Q35: 110 | R35: 110 | S35: 110 | T35: 115
A36: exhibition | B36: 0 | C36: 0 | D36: 0 | E36: 0 | F36: 0 | G36: 0 | H36: 0 | I36: 0 | J36: 2 | K36: 7 | L36: 13 | N36: 42 | O36: 117 | P36: 70 | Q36: 117 | R36: 80 | S36: 98 | T36: 130
A37: exhibition | B37: 0 | C37: 0 | D37: 0 | E37: 0 | F37: 0 | G37: 0 | H37: 0 | I37: 0 | J37: 0 | K37: 0 | L37: 0 | N37: 0.02189781 | O37: 0.19708029 | P37: 0.13138686 | Q37: 0.19708029 | R37: 0.19708029 | S37: 0.19708029 | T37: 0.16058394
A38: exhibition | B38: NaN | C38: NaN | D38: NaN | E38: NaN | F38: NaN | G38: NaN | H38: NaN | I38: NaN | J38: 0 | K38: 0 | L38: 0 | N38: 0.066666667 | O38: 0.1875 | P38: 0.20454545 | Q38: 0.1875 | R38: 0.25233645 | S38: 0.216 | T38: 0.14473684
A39: exhibition | B39: 0 | C39: 0 | D39: 0 | E39: 0 | F39: 0 | G39: 0 | H39: 0 | I39: 0 | J39: 0 | K39: 0 | L39: 0 | M39: 0.215 | N39: 0.032967033 | O39: 0.19217082 | P39: 0.16 | Q39: 0.19217082 | R39: 0.22131148 | S39: 0.20610687 | T39: 0.15224913
A40: exhibition | B40: 0.99534188 | C40: 0.99534188 | D40: 0.99534188 | E40: 0.99534188 | F40: 0.99534188 | G40: 0.99534188 | H40: 0.99534188 | I40: 0.99534188 | J40: 0.99527388 | K40: 0.99510387 | L40: 0.99489987 | N40: 0.99401584 | O40: 0.9922818 | P40: 0.99357383 | Q40: 0.9922818 | R40: 0.99353983 | S40: 0.99292782 | T40: 0.99166978
A43: fashion | B43: 0 | C43: 0 | D43: 0 | E43: 0 | F43: 0 | G43: 0 | H43: 0 | I43: 0 | J43: 0 | K43: 1 | L43: 3 | N43: 5 | O43: 3 | P43: 3 | Q43: 3 | R43: 3 | S43: 3 | T43: 1
A44: fashion | B44: 29383 | C44: 29383 | D44: 29383 | E44: 29383 | F44: 29383 | G44: 29383 | H44: 29383 | I44: 29383 | J44: 29383 | K44: 29383 | L44: 29383 | N44: 29383 | O44: 29380 | P44: 29383 | Q44: 29380 | R44: 29383 | S44: 29382 | T44: 29382
A45: fashion | B45: 28 | C45: 28 | D45: 28 | E45: 28 | F45: 28 | G45: 28 | H45: 28 | I45: 28 | J45: 28 | K45: 27 | L45: 25 | N45: 23 | O45: 25 | P45: 25 | Q45: 25 | R45: 25 | S45: 25 | T45: 27
A46: fashion | B46: 0 | C46: 0 | D46: 0 | E46: 0 | F46: 0 | G46: 0 | H46: 0 | I46: 0 | J46: 0 | K46: 0 | L46: 0 | N46: 0 | O46: 3 | P46: 0 | Q46: 3 | R46: 0 | S46: 1 | T46: 1
A47: fashion | B47: 0.02 | C47: 0 | D47: 0 | E47: 0 | F47: 0 | G47: 0 | H47: 0 | I47: 0 | J47: 0 | K47: 0.035714286 | L47: 0.10714286 | N47: 0.17857143 | O47: 0.10714286 | P47: 0.10714286 | Q47: 0.10714286 | R47: 0.10714286 | S47: 0.10714286 | T47: 0.035714286
A48: fashion | B48: NaN | C48: NaN | D48: NaN | E48: NaN | F48: NaN | G48: NaN | H48: NaN | I48: NaN | J48: NaN | K48: 1 | L48: 1 | N48: 1 | O48: 0.5 | P48: 1 | Q48: 0.5 | R48: 1 | S48: 0.75 | T48: 0.5
A49: fashion | B49: 0 | C49: 0 | D49: 0 | E49: 0 | F49: 0 | G49: 0 | H49: 0 | I49: 0 | J49: 0 | K49: 0.068965517 | L49: 0.19354839 | M49: 0.1764 | N49: 0.3030303 | O49: 0.17647059 | P49: 0.19354839 | Q49: 0.17647059 | R49: 0.19354839 | S49: 0.1875 | T49: 0.066666667
...

Sheet 6. For ACIS 2014
C1: BASELINE | F1: 7/28/2014 for ACIS 2014
D2: Changed in code
A3: MULTI CLASS | C3: Event | D3: F1 | F3: BIN CLASS | H3: F1
B4: 1 | C4: conference | D4: 0.11382114 | G4: event | H4: 0.43576765
C5: fashion | D5: 0.3030303 | G5: non_event | H5: 0.95718179
C6: concert | D6: 0.47622329
C7: non_event | D7: 0.95754433
C8: sports | D8: 0.070175439
C9: protest | D9: 0.59555556
C10: other | D10: 0
C11: exhibition | D11: 0.012269939
C12: theater_dance | D12: 0.42857143
C13: AVERAGE | D13: =AVERAGE(D4:D12) -> 0.32857682 | L13: =(D28-D13)/D13 -> 0.0094698671
C16: YAGO ENRICHMENT | F16: 7/29/2014 for ACIS 2014
D17: Changed in code
A18: MULTI CLASS | C18: Event | D18: F1
C19: conference | D19: 0.128
C20: fashion | D20: 0.3030303
C21: concert | D21: 0.48101266
C22: non_event | D22: 0.95771149
C23: sports | D23: 0.070484581
C24: protest | D24: 0.59821429
C25: other | D25: 0
C26: exhibition | D26: 0.012578616
C27: theater_dance | D27: 0.4341637
C28: AVERAGE | D28: =AVERAGE(D19:D27) -> 0.3316884

Sheet 1. Exp-based
B2: 2 CLASS CLASSIFICATION
L5: VM1 | U5: VM2
D8: EXP-BASED RESULT
A9: Run | B9: 1 | C9: 2 | D9: 3 | E9: 4 | F9: 5 | G9: 6 | H9: 7 | I9: 8 | J9: 9 | K9: 10 | L9: 11 | M9: 12 | N9: 13 | O9: 14 | P9: 15 | Q9: 16 | R9: 17 | S9: 18 | T9: 19 | U9: 20 | V9: 21 | W9: 22 | X9: 23 | Y9: 24 | Z9: 25
A10: Pre | B10: 0.74348624 | C10: 0.74678899 | D10: 0.73174312 | E10: 0.75155963 | F10: 0.72220183 | G10: 0.74458716 | H10: 0.77027523 | I10: 0.75779817 | J10: 0.72917431 | K10: 0.75082569 | L10: 0.75082569 | M10: 0.72807339 | N10: 0.76146789 | O10: 0.72990826 | P10: 0.74825688 | Q10: 0.73541284 | R10: 0.76623853 | S10: 0.75192661 | T10: 0.74201835 | U10: 0.73431193 | V10: 0.72550459 | W10: 0.73211009 | X10: 0.76440367 | Y10: 0.7346789 | Z10: 0.72183486
A11: Rec | B11: 0.35444367 | C11: 0.34691442 | D11: 0.3585686 | E11: 0.36279894 | F11: 0.34405594 | G11: 0.34337451 | H11: 0.35831342 | I11: 0.35347484 | J11: 0.34610695 | K11: 0.36071932 | L11: 0.35539343 | M11: 0.35071593 | N11: 0.35610091 | O11: 0.35385163 | P11: 0.3553503 | Q11: 0.35494155 | R11: 0.35710621 | S11: 0.35315408 | T11: 0.35825656 | U11: 0.35751295 | V11: 0.34080331 | W11: 0.35797596 | X11: 0.36194613 | Y11: 0.34222222 | Z11: 0.35238266
A12: F1 | B12: 0.48003791 | C12: 0.4737516 | D12: 0.48129375 | E12: 0.48936679 | F12: 0.4660746 | G12: 0.47000232 | H12: 0.48910637 | I12: 0.48208241 | J12: 0.46940704 | K12: 0.4873169 | L12: 0.48243339 | M12: 0.47339537 | N12: 0.4852666 | O12: 0.47663551 | P12: 0.48186222 | Q12: 0.47879584 | R12: 0.48716752 | S12: 0.48059106 | T12: 0.48321185 | U12: 0.48089402 | V12: 0.46375792 | W12: 0.48083876 | X12: 0.49127358 | Y12: 0.46693878 | Z12: 0.4735765
A13: ACC | B13: 0.85077012 | C13: 0.846282 | D13: 0.8538642 | E13: 0.85468022 | F13: 0.84669001 | G13: 0.84441195 | H13: 0.85090612 | I13: 0.84913808 | J13: 0.84726803 | K13: 0.85362619 | L13: 0.85073612 | M13: 0.8499201 | N13: 0.85032811 | O13: 0.85148414 | P13: 0.85090612 | Q13: 0.85165414 | R13: 0.85053211 | S13: 0.84941008 | T13: 0.85294618 | U13: 0.85311618 | V13: 0.84454796 | W13: 0.85352419 | X13: 0.85332019 | Y13: 0.84458196 | Z13: 0.85131413
D15: COMPARE TO BASELINE RESULT
A16: Run | B16: 1 | C16: 2 | D16: 3 | E16: 4 | F16: 5 | G16: 6 | H16: 7 | I16: 8 | J16: 9 | K16: 10 | L16: 11 | M16: 12 | N16: 13 | O16: 14 | P16: 15 | Q16: 16 | R16: 17 | S16: 18 | T16: 19 | U16: 20 | V16: 21 | W16: 22 | X16: 23 | Y16: 24 | Z16: 25
A17: Pre_exp | B17: 0.74348624 | C17: 0.74678899 | D17: 0.73174312 | E17: 0.75155963 | F17: 0.72220183 | G17: 0.74458716 | H17: 0.77027523 | I17: 0.75779817 | J17: 0.72917431 | K17: 0.75082569 | L17: 0.75082569 | M17: 0.72807339 | N17: 0.76146789 | O17: 0.72990826 | P17: 0.74825688 | Q17: 0.73541284 | R17: 0.76623853 | S17: 0.75192661 | T17: 0.74201835 | U17: 0.73431193 | V17: 0.72550459 | W17: 0.73211009 | X17: 0.76440367 | Y17: 0.7346789 | Z17: 0.72183486
A18: Rec_exp | B18: 0.35444367 | C18: 0.34691442 | D18: 0.3585686 | E18: 0.36279894 | F18: 0.34405594 | G18: 0.34337451 | H18: 0.35831342 | I18: 0.35347484 | J18: 0.34610695 | K18: 0.36071932 | L18: 0.35539343 | M18: 0.35071593 | N18: 0.35610091 | O18: 0.35385163 | P18: 0.3553503 | Q18: 0.35494155 | R18: 0.35710621 | S18: 0.35315408 | T18: 0.35825656 | U18: 0.35751295 | V18: 0.34080331 | W18: 0.35797596 | X18: 0.36194613 | Y18: 0.34222222 | Z18: 0.35238266
A19: F1_exp | B19: 0.48003791 | C19: 0.4737516 | D19: 0.48129375 | E19: 0.48936679 | F19: 0.4660746 | G19: 0.47000232 | H19: 0.48910637 | I19: 0.48208241 | J19: 0.46940704 | K19: 0.4873169 | L19: 0.48243339 | M19: 0.47339537 | N19: 0.4852666 | O19: 0.47663551 | P19: 0.48186222 | Q19: 0.47879584 | R19: 0.48716752 | S19: 0.48059106 | T19: 0.48321185 | U19: 0.48089402 | V19: 0.46375792 | W19: 0.48083876 | X19: 0.49127358 | Y19: 0.46693878 | Z19: 0.4735765 | AA19: =COUNTIF(B19:Z19,">0.4794") -> 15 | AB19: =15/25 -> 0.6
A20: ACC_exp | B20: 0.85077012 | C20: 0.846282 | D20: 0.8538642 | E20: 0.85468022 | F20: 0.84669001 | G20: 0.84441195 | H20: 0.85090612 | I20: 0.84913808 | J20: 0.84726803 | K20: 0.85362619 | L20: 0.85073612 | M20: 0.8499201 | N20: 0.85032811 | O20: 0.85148414 | P20: 0.85090612 | Q20: 0.85165414 | R20: 0.85053211 | S20: 0.84941008 | T20: 0.85294618 | U20: 0.85311618 | V20: 0.84454796 | W20: 0.85352419 | X20: 0.85332019 | Y20: 0.84458196 | Z20: 0.85131413 | AB20: =MAX(B19:Z19) -> 0.49127358
A21: Pvs_best | B21: 0.4794 | C21: 0.4794 | D21: 0.4794 | E21: 0.4794 | F21: 0.4794 | G21: 0.4794 | H21: 0.4794 | I21: 0.4794 | J21: 0.4794 | K21: 0.4794 | L21: 0.4794 | M21: 0.4794 | N21: 0.4794 | O21: 0.4794 | P21: 0.4794 | Q21: 0.4794 | R21: 0.4794 | S21: 0.4794 | T21: 0.4794 | U21: 0.4794 | V21: 0.4794 | W21: 0.4794 | X21: 0.4794 | Y21: 0.4794 | Z21: 0.4794
A22: Pre_bas | B22: 0.35302752 | C22: 0.056146789 | D22: 0.16513761 | E22: 0.25944954 | F22: 0.38238532 | G22: 0.16036697 | H22: 0.019449541 | I22: 0.13137615 | J22: 0.097614679 | K22: 0.10788991 | L22: 0.19559633 | M22: 0.019816514 | N22: 0.44183486 | O22: 0.5306422 | P22: 0.30972477 | Q22: 0.5706422 | R22: 0.45431193 | S22: 0.089541284 | T22: 0.095779817 | U22: 0.038165138 | V22: 0.43302752 | W22: 0.36733945 | X22: 0.5893578 | Y22: 0.030825688 | Z22: 0.21431193
A23: Rec_bas | B23: 0.084489724 | C23: 0.16122234 | D23: 0.077439339 | E23: 0.081208362 | F23: 0.13768499 | G23: 0.080806213 | H23: 0.31360947 | I23: 0.15364807 | J23: 0.14164004 | K23: 0.13738318 | L23: 0.14772727 | M23: 0.2 | N23: 0.073860499 | O23: 0.095552765 | P23: 0.067342217 | Q23: 0.087605634 | R23: 0.10813171 | S23: 0.062773347 | T23: 0.11035941 | U23: 0.2007722 | V23: 0.070599497 | W23: 0.10986719 | X23: 0.095794811 | Y23: 0.25609756 | Z23: 0.087793145
A24: F1_bas | B24: 0.13634753 | C24: 0.08328797 | D24: 0.1054358 | E24: 0.12369871 | F24: 0.2024677 | G24: 0.10746342 | H24: 0.036627505 | I24: 0.14164194 | J24: 0.1155768 | K24: 0.12086331 | L24: 0.16832465 | M24: 0.0360601 | N24: 0.12656365 | O24: 0.16194423 | P24: 0.11063049 | Q24: 0.15189255 | R24: 0.17468604 | S24: 0.073805203 | T24: 0.10255403 | U24: 0.064138144 | V24: 0.12140542 | W24: 0.16914498 | X24: 0.16480246 | Y24: 0.055027841 | Z24: 0.12456009
A25: ACC_bas | B25: 0.58563123 | C25: 0.88548502 | D25: 0.74036925 | E25: 0.65941314 | F25: 0.72088674 | G25: 0.75318758 | H25: 0.90520554 | I25: 0.85247016 | J25: 0.8615824 | K25: 0.85457822 | L25: 0.82091734 | M25: 0.90183945 | N25: 0.43497331 | O25: 0.49114277 | P25: 0.538608 | Q25: 0.40957465 | R25: 0.60225766 | S25: 0.79177859 | T25: 0.84468396 | U25: 0.89680732 | V25: 0.4192989 | W25: 0.66563531 | X25: 0.44653361 | Y25: 0.90190745 | Z25: 0.72088674
A68: NEW - RUN WITH FULL TEST SET
A69: C=2^5 | B69: NO REPLACEMENT
A71: Column1 | B71: New | C71: Baseline
A72: conference | B72: 0.128 | C72: 0.1764
A73: fashion | B73: 0.3030303 | C73: 0.5
A74: concert | B74: 0.48101266 | C74: 0.5264
A75: non_event | B75: 0.95771149 | C75: 0.9229
A76: sports | B76: 0.070484581 | C76: 0.1495
A77: protest | B77: 0.59821429 | C77: 0.6457
A78: other | B78: 0 | C78: 0.1119
A79: exhibition | B79: 0.012578616 | C79: 0.215
A80: theater_dance | B80: 0.4341637 | C80: 0.4
A81: AVERAGE | B81: =AVERAGE(B72:B80) -> 0.3316884 | C81: =AVERAGE(C72:C80) -> 0.40531111

Sheet 3. Baseline - F1
D1: F1 SCORES BY C | V1: Explain-based Wnet1
A2: C | C2: 0.01 | D2: 1 | E2: 100 | F2: 500 | G2: 1000 | H2: 2000 | I2: 3000 | J2: 5000 | K2: 7000 | L2: 10000 | M2: 20000 | N2: 32768 | O2: ='2. Baseline - Full'!N2 -> 50000 | P2: ='2. Baseline - Full'!O2 -> 100000 | Q2: ='2. Baseline - Full'!P2 -> 130000 | R2: ='2. Baseline - Full'!Q2 -> 150000 | S2: ='2. Baseline - Full'!R2 -> 200000 | T2: ='2. Baseline - Full'!S2 -> 400000 | U2: ='2. Baseline - Full'!T2 -> 700000 | V2: ='2. Baseline - Full'!U2 -> 400000 | W2: ='2. Baseline - Full'!V2 -> 400000
A3: theater_dance | B3: True Positive | C3: 0 | D3: 0 | E3: 0 | F3: 2 | G3: 3 | H3: 10 | I3: 15 | J3: 27 | K3: 40 | L3: 52 | M3: 62 | O3: 0.3862069 | P3: 0.3862069 | Q3: 0.3862069 | R3: 0.3862069 | S3: 0.3862069 | T3: 0.3862069
B4: True Negative | C4: 29291 | D4: 29291 | E4: 29291 | F4: 29289 | G4: 29286 | H4: 29274 | I4: 29264 | J4: 29239 | K4: 29224 | L4: 29209 | M4: 29192 | O4: 0.49584232 | P4: 0.49584232 | Q4: 0.49584232 | R4: 0.49584232 | S4: 0.49584232 | T4: 0.49584232
B5: False Positive | C5: 120 | D5: 120 | E5: 120 | F5: 118 | G5: 117 | H5: 110 | I5: 105 | J5: 93 | K5: 80 | L5: 68 | M5: 58 | O5: 0.1969697 | P5: 0.1969697 | Q5: 0.1969697 | R5: 0.1969697 | S5: 0.1969697 | T5: 0.1969697
B6: False Negative | C6: 0 | D6: 0 | E6: 0 | F6: 2 | G6: 5 | H6: 17 | I6: 27 | J6: 52 | K6: 67 | L6: 82 | M6: 99 | O6: 0.16 | P6: 0.16 | Q6: 0.16 | R6: 0.16 | S6: 0.16 | T6: 0.16
B7: Precision | C7: 0 | D7: 0 | E7: 0 | F7: 0.016666667 | G7: 0.025 | H7: 0.083333333 | I7: 0.125 | J7: 0.225 | K7: 0.33333333 | L7: 0.43333333 | M7: 0.51666667 | O7: 0.19354839 | P7: 0.19354839 | Q7: 0.19354839 | R7: 0.19354839 | S7: 0.19354839 | T7: 0.19354839
B8: Recall | C8: NaN | D8: NaN | E8: NaN | F8: 0.5 | G8: 0.375 | H8: 0.37037037 | I8: 0.35714286 | J8: 0.34177215 | K8: 0.37383178 | L8: 0.3880597 | M8: 0.38509317 | O8: 0.95442073 | P8: 0.95442073 | Q8: 0.95442073 | R8: 0.95442073 | S8: 0.95442073 | T8: 0.95442073
B9: F1 | C9: 0 | D9: 0 | E9: 0 | F9: 0.032258065 | G9: 0.046875 | H9: 0.13605442 | I9: 0.18518519 | J9: 0.27135678 | K9: 0.35242291 | L9: 0.40944882 | M9: 0.44128114 | N9: 0.4 | O9: ='2. Baseline - Full'!N9 -> 0.41304348 | P9: ='2. Baseline - Full'!O9 -> 0.36426117 | Q9: ='2. Baseline - Full'!P9 -> 0.3862069 | R9: ='2. Baseline - Full'!Q9 -> 0.36426117 | S9: ='2. Baseline - Full'!R9 -> 0.36860068 | T9: ='2. Baseline - Full'!S9 -> 0.38869258 | U9: ='2. Baseline - Full'!T9 -> 0.38405797 | V9: ='2. Baseline - Full'!U9 -> 0.36805556 | W9: ='2. Baseline - Full'!V9 -> 0.36912752
B10: Accuracy | C10: 0.99591989 | D10: 0.99591989 | E10: 0.99591989 | F10: 0.99591989 | G10: 0.99585189 | H10: 0.99568189 | I10: 0.99551188 | J10: 0.99506987 | K10: 0.99500187 | L10: 0.99489987 | M10: 0.99466186 | O10: 0.5915493 | P10: 0.5915493 | Q10: 0.5915493 | R10: 0.5915493 | S10: 0.5915493 | T10: 0.5915493 | U10: 0.5915493 | V10: 0.5915493 | W10: 0.5915493
O11: 0.078740157 | P11: 0.078740157 | Q11: 0.078740157 | R11: 0.078740157 | S11: 0.078740157 | T11: 0.078740157 | U11: 0.078740157 | V11: 0.078740157 | W11: 0.078740157
A13: concert | B13: True Positive | C13: 0 | D13: 0 | E13: 0 | F13: 39 | G13: 127 | H13: 231 | I13: 287 | J13: 410 | K13: 481 | L13: 541 | M13: 625
B14: True Negative | C14: 27522 | D14: 27522 | E14: 27522 | F14: 27514 | G14: 27484 | H14: 27453 | I14: 27433 | J14: 27385 | K14: 27364 | L14: 27331 | M14: 27261
B15: False Positive | C15: 1889 | D15: 1889 | E15: 1889 | F15: 1850 | G15: 1762 | H15: 1658 | I15: 1602 | J15: 1479 | K15: 1408 | L15: 1348 | M15: 1264
B16: False Negative | C16: 0 | D16: 0 | E16: 0 | F16: 8 | G16: 38 | H16: 69 | I16: 89 | J16: 137 | K16: 158 | L16: 191 | M16: 261
B17: Precision | C17: 0 | D17: 0 | E17: 0 | F17: 0.020645844 | G17: 0.067231339 | H17: 0.12228692 | I17: 0.15193224 | J17: 0.21704606 | K17: 0.25463208 | L17: 0.28639492 | M17: 0.33086289
B18: Recall | C18: NaN | D18: NaN | E18: NaN | F18: 0.82978723 | G18: 0.76969697 | H18: 0.77 | I18: 0.76329787 | J18: 0.74954296 | K18: 0.75273865 | L18: 0.73907104 | M18: 0.70541761
B19: F1 | C19: 0 | D19: 0 | E19: 0 | F19: 0.040289256 | G19: 0.12366115 | H19: 0.21105528 | I19: 0.25342163 | J19: 0.33661741 | K19: 0.38053797 | L19: 0.41281953 | M19: 0.45045045 | N19: 0.5264 | O19: ='2. Baseline - Full'!N19 -> 0.48905109 | P19: ='2. Baseline - Full'!O19 -> 0.48217417 | Q19: ='2. Baseline - Full'!P19 -> 0.49584232 | R19: ='2. Baseline - Full'!Q19 -> 0.48217417 | S19: ='2. Baseline - Full'!R19 -> 0.48543689 | T19: ='2. Baseline - Full'!S19 -> 0.48477683 | U19: ='2. Baseline - Full'!T19 -> 0.45968217 | V19: ='2. Baseline - Full'!U19 -> 0.48300117 | W19: ='2. Baseline - Full'!V19 -> 0.48831015
B20: Accuracy | C20: 0.93577233 | D20: 0.93577233 | E20: 0.93577233 | F20: 0.93682636 | G20: 0.93879841 | H20: 0.94128047 | I20: 0.94250451 | J20: 0.94505457 | K20: 0.94675462 | L20: 0.94767264 | M20: 0.94814865
A23: conference | B23: True Positive | C23: 0 | D23: 0 | E23: 0 | F23: 0 | G23: 0 | H23: 0 | I23: 0 | J23: 0 | K23: 0 | L23: 0 | M23: 2
B24: True Negative | C24: 29299 | D24: 29299 | E24: 29299 | F24: 29299 | G24: 29299 | H24: 29299 | I24: 29299 | J24: 29299 | K24: 29299 | L24: 29297 | M24: 29296
B25: False Positive | C25: 112 | D25: 112 | E25: 112 | F25: 112 | G25: 112 | H25: 112 | I25: 112 | J25: 112 | K25: 112 | L25: 112 | M25: 110
B26: False Negative | C26: 0 | D26: 0 | E26: 0 | F26: 0 | G26: 0 | H26: 0 | I26: 0 | J26: 0 | K26: 0 | L26: 2 | M26: 3
B27: Precision | C27: 0 | D27: 0 | E27: 0 | F27: 0 | G27: 0 | H27: 0 | I27: 0 | J27: 0 | K27: 0 | L27: 0 | M27: 0.017857143
B28: Recall | C28: NaN | D28: NaN | E28: NaN | F28: NaN | G28: NaN | H28: NaN | I28: NaN | J28: NaN | K28: NaN | L28: 0 | M28: 0.4
B29: F1 | C29: 0 | D29: 0 | E29: 0 | F29: 0 | G29: 0 | H29: 0 | I29: 0 | J29: 0 | K29: 0 | L29: 0 | M29: 0.034188034 | N29: 0.5137 | O29: ='2. Baseline - Full'!N29 -> 0.13953488 | P29: ='2. Baseline - Full'!O29 -> 0.18461538 | Q29: ='2. Baseline - Full'!P29 -> 0.1969697 | R29: ='2. Baseline - Full'!Q29 -> 0.18461538 | S29: ='2. Baseline - Full'!R29 -> 0.18461538 | T29: ='2. Baseline - Full'!S29 -> 0.18461538 | U29: ='2. Baseline - Full'!T29 -> 0.16541353 | V29: ='2. Baseline - Full'!U29 -> 0.20740741 | W29: ='2. Baseline - Full'!V29 -> 0.171875
B30: Accuracy | C30: 0.9961919 | D30: 0.9961919 | E30: 0.9961919 | F30: 0.9961919 | G30: 0.9961919 | H30: 0.9961919 | I30: 0.9961919 | J30: 0.9961919 | K30: 0.9961919 | L30: 0.9961239 | M30: 0.9961579
A33: exhibition | B33: True Positive | C33: 0 | D33: 0 | E33: 0 | F33: 0 | G33: 0 | H33: 0 | I33: 0 | J33: 0 | K33: 0 | L33: 0 | M33: 0
B34: True Negative | C34: 29274 | D34: 29274 | E34: 29274 | F34: 29274 | G34: 29274 | H34: 29274 | I34: 29274 | J34: 29274 | K34: 29272 | L34: 29267 | M34: 29261
B35: False Positive | C35: 137 | D35: 137 | E35: 137 | F35: 137 | G35: 137 | H35: 137 | I35: 137 | J35: 137 | K35: 137 | L35: 137 | M35: 137
B36: False Negative | C36: 0 | D36: 0 | E36: 0 | F36: 0 | G36: 0 | H36: 0 | I36: 0 | J36: 0 | K36: 2 | L36: 7 | M36: 13
B37: Precision | C37: 0 | D37: 0 | E37: 0 | F37: 0 | G37: 0 | H37: 0 | I37: 0 | J37: 0 | K37: 0 | L37: 0 | M37: 0
B38: Recall | C38: NaN | D38: NaN | E38: NaN | F38: NaN | G38: NaN | H38: NaN | I38: NaN | J38: NaN | K38: 0 | L38: 0 | M38: 0
B39: F1 | C39: 0 | D39: 0 | E39: 0 | F39: 0 | G39: 0 | H39: 0 | I39: 0 | J39: 0 | K39: 0 | L39: 0 | M39: 0 | N39: 0.215 | O39: ='2. Baseline - Full'!N39 -> 0.032967033 | P39: ='2. Baseline - Full'!O39 -> 0.19217082 | Q39: ='2. Baseline - Full'!P39 -> 0.16 | R39: ='2. Baseline - Full'!Q39 -> 0.19217082 | S39: ='2. Baseline - Full'!R39 -> 0.22131148 | T39: ='2. Baseline - Full'!S39 -> 0.20610687 | U39: ='2. Baseline - Full'!T39 -> 0.15224913 | V39: ='2. Baseline - Full'!U39 -> 0.16342412 | W39: ='2. Baseline - Full'!V39 -> 0.21132075
B40: Accuracy | C40: 0.99534188 | D40: 0.99534188 | E40: 0.99534188 | F40: 0.99534188 | G40: 0.99534188 | H40: 0.99534188 | I40: 0.99534188 | J40: 0.99534188 | K40: 0.99527388 | L40: 0.99510387 | M40: 0.99489987
A43: fashion | B43: True Positive | C43: 0 | D43: 0 | E43: 0 | F43: 0 | G43: 0 | H43: 0 | I43: 0 | J43: 0 | K43: 0 | L43: 1 | M43: 3
B44: True Negative | C44: 29383 | D44: 29383 | E44: 29383 | F44: 29383 | G44: 29383 | H44: 29383 | I44: 29383 | J44: 29383 | K44: 29383 | L44: 29383 | M44: 29383
B45: False Positive | C45: 28 | D45: 28 | E45: 28 | F45: 28 | G45: 28 | H45: 28 | I45: 28 | J45: 28 | K45: 28 | L45: 27 | M45: 25
B46: False Negative | C46: 0 | D46: 0 | E46: 0 | F46: 0 | G46: 0 | H46: 0 | I46: 0 | J46: 0 | K46: 0 | L46: 0 | M46: 0
B47: Precision | C47: 0.02 | D47: 0 | E47: 0 | F47: 0 | G47: 0 | H47: 0 | I47: 0 | J47: 0 | K47: 0 | L47: 0.035714286 | M47: 0.10714286
...

Sheet 2. Baseline - Full
U1: Ex-based
A2: c | C2: 0.01 | D2: 1 | E2: 100 | F2: 500 | G2: 1000 | H2: 2000 | I2: 3000 | J2: 5000 | K2: 7000 | L2: 10000 | M2: 20000 | N2: 50000 | O2: 100000 | P2: 130000 | Q2: 150000 | R2: 200000 | S2: 400000 | T2: 700000 | U2: 400000 | V2: 400000
A3: theater_dance | B3: True Positive | C3: 0 | D3: 0 | E3: 0 | F3: 2 | G3: 3 | H3: 10 | I3: 15 | J3: 27 | K3: 40 | L3: 52 | M3: 62 | N3: 57 | O3: 53 | P3: 56 | Q3: 53 | R3: 54 | S3: 55 | T3: 53 | U3: 53 | V3: 55
B4: True Negative | C4: 29291 | D4: 29291 | E4: 29291 | F4: 29289 | G4: 29286 | H4: 29274 | I4: 29264 | J4: 29239 | K4: 29224 | L4: 29209 | M4: 29192 | N4: 29192 | O4: 29173 | P4: 29177 | Q4: 29173 | R4: 29172 | S4: 29183 | T4: 29188 | U4: 29176 | V4: 29168
B5: False Positive | C5: 120 | D5: 120 | E5: 120 | F5: 118 | G5: 117 | H5: 110 | I5: 105 | J5: 93 | K5: 80 | L5: 68 | M5: 58 | N5: 63 | O5: 67 | P5: 64 | Q5: 67 | R5: 66 | S5: 65 | T5: 67 | U5: 67 | V5: 65
B6: False Negative | C6: 0 | D6: 0 | E6: 0 | F6: 2 | G6: 5 | H6: 17 | I6: 27 | J6: 52 | K6: 67 | L6: 82 | M6: 99 | N6: 99 | O6: 118 | P6: 114 | Q6: 118 | R6: 119 | S6: 108 | T6: 103 | U6: 115 | V6: 123
B7: Precision | C7: 0 | D7: 0 | E7: 0 | F7: 0.016666667 | G7: 0.025 | H7: 0.083333333 | I7: 0.125 | J7: 0.225 | K7: 0.33333333 | L7: 0.43333333 | M7: 0.51666667 | N7: 0.475 | O7: 0.44166667 | P7: 0.46666667 | Q7: 0.44166667 | R7: 0.45 | S7: 0.45833333 | T7: 0.44166667 | U7: 0.44166667 | V7: 0.45833333
B8: Recall | C8: NaN | D8: NaN | E8: NaN | F8: 0.5 | G8: 0.375 | H8: 0.37037037 | I8: 0.35714286 | J8: 0.34177215 | K8: 0.37383178 | L8: 0.3880597 | M8: 0.38509317 | N8: 0.36538462 | O8: 0.30994152 | P8: 0.32941176 | Q8: 0.30994152 | R8: 0.31213873 | S8: 0.33742331 | T8: 0.33974359 | U8: 0.31547619 | V8: 0.30898876
B9: F1 | C9: 0 | D9: 0 | E9: 0 | F9: 0.032258065 | G9: 0.046875 | H9: 0.13605442 | I9: 0.18518519 | J9: 0.27135678 | K9: 0.35242291 | L9: 0.40944882 | M9: 0.44128114 | N9: 0.41304348 | O9: 0.36426117 | P9: 0.3862069 | Q9: 0.36426117 | R9: 0.36860068 | S9: 0.38869258 | T9: 0.38405797 | U9: 0.36805556 | V9: 0.36912752
B10: Accuracy | C10: 0.99591989 | D10: 0.99591989 | E10: 0.99591989 | F10: 0.99591989 | G10: 0.99585189 | H10: 0.99568189 | I10: 0.99551188 | J10: 0.99506987 | K10: 0.99500187 | L10: 0.99489987 | M10: 0.99466186 | N10: 0.99449186 | O10: 0.99370984 | P10: 0.99394784 | Q10: 0.99370984 | R10: 0.99370984 | S10: 0.99411785 | T10: 0.99421985 | U10: 0.99381184 | V10: 0.99360783
A13: concert | B13: True Positive | C13: 0 | D13: 0 | E13: 0 | F13: 39 | G13: 127 | H13: 231 | I13: 287 | J13: 410 | K13: 481 | L13: 541 | M13: 625 | N13: 737 | O13: 825 | P13: 805 | Q13: 825 | R13: 800 | S13: 820 | T13: 781 | U13: 824 | V13: 825
B14: True Negative | C14: 27522 | D14: 27522 | E14: 27522 | F14: 27514 | G14: 27484 | H14: 27453 | I14: 27433 | J14: 27385 | K14: 27364 | L14: 27331 | M14: 27261 | N14: 27134 | O14: 26814 | P14: 26969 | Q14: 26814 | R14: 26915 | S14: 26848 | T14: 26794 | U14: 26823 | V14: 26857
B15: False Positive | C15: 1889 | D15: 1889 | E15: 1889 | F15: 1850 | G15: 1762 | H15: 1658 | I15: 1602 | J15: 1479 | K15: 1408 | L15: 1348 | M15: 1264 | N15: 1152 | O15: 1064 | P15: 1084 | Q15: 1064 | R15: 1089 | S15: 1069 | T15: 1108 | U15: 1065 | V15: 1064
B16: False Negative | C16: 0 | D16: 0 | E16: 0 | F16: 8 | G16: 38 | H16: 69 | I16: 89 | J16: 137 | K16: 158 | L16: 191 | M16: 261 | N16: 388 | O16: 708 | P16: 553 | Q16: 708 | R16: 607 | S16: 674 | T16: 728 | U16: 699 | V16: 665
B17: Precision | C17: 0 | D17: 0 | E17: 0 | F17: 0.020645844 | G17: 0.067231339 | H17: 0.12228692 | I17: 0.15193224 | J17: 0.21704606 | K17: 0.25463208 | L17: 0.28639492 | M17: 0.33086289 | N17: 0.39015352 | O17: 0.43673902 | P17: 0.4261514 | Q17: 0.43673902 | R17: 0.4235045 | S17: 0.43409211 | T17: 0.41344627 | U17: 0.43620963 | V17: 0.43673902
B18: Recall | C18: NaN | D18: NaN | E18: NaN | F18: 0.82978723 | G18: 0.76969697 | H18: 0.77 | I18: 0.76329787 | J18: 0.74954296 | K18: 0.75273865 | L18: 0.73907104 | M18: 0.70541761 | N18: 0.65511111 | O18: 0.53816047 | P18: 0.59278351 | Q18: 0.53816047 | R18: 0.56858564 | S18: 0.54886212 | T18: 0.5175613 | U18: 0.54103743 | V18: 0.55369128
B19: F1 | C19: 0 | D19: 0 | E19: 0 | F19: 0.040289256 | G19: 0.12366115 | H19: 0.21105528 | I19: 0.25342163 | J19: 0.33661741 | K19: 0.38053797 | L19: 0.41281953 | M19: 0.45045045 | N19: 0.48905109 | O19: 0.48217417 | P19: 0.49584232 | Q19: 0.48217417 | R19: 0.48543689 | S19: 0.48477683 | T19: 0.45968217 | U19: 0.48300117 | V19: 0.48831015
B20: Accuracy | C20: 0.93577233 | D20: 0.93577233 | E20: 0.93577233 | F20: 0.93682636 | G20: 0.93879841 | H20: 0.94128047 | I20: 0.94250451 | J20: 0.94505457 | K20: 0.94675462 | L20: 0.94767264 | M20: 0.94814865 | N20: 0.94763864 | O20: 0.93975043 | P20: 0.94434055 | Q20: 0.93975043 | R20: 0.9423345 | S20: 0.94073646 | T20: 0.93757438 | U20: 0.94002244 | V20: 0.94121247
A23: conference | B23: True Positive | C23: 0 | D23: 0 | E23: 0 | F23: 0 | G23: 0 | H23: 0 | I23: 0 | J23: 0 | K23: 0 | L23: 0 | M23: 2 | N23: 9 | O23: 12 | P23: 13 | Q23: 12 | R23: 12 | S23: 12 | T23: 11 | U23: 14 | V23: 11
B24: True Negative | C24: 29299 | D24: 29299 | E24: 29299 | F24: 29299 | G24: 29299 | H24: 29299 | I24: 29299 | J24: 29299 | K24: 29299 | L24: 29297 | M24: 29296 | N24: 29291 | O24: 29293 | P24: 29292 | Q24: 29293 | R24: 29293 | S24: 29293 | T24: 29289 | U24: 29290 | V24: 29294
B25: False Positive | C25: 112 | D25: 112 | E25: 112 | F25: 112 | G25: 112 | H25: 112 | I25: 112 | J25: 112 | K25: 112 | L25: 112 | M25: 110 | N25: 103 | O25: 100 | P25: 99 | Q25: 100 | R25: 100 | S25: 100 | T25: 101 | U25: 98 | V25: 101
B26: False Negative | C26: 0 | D26: 0 | E26: 0 | F26: 0 | G26: 0 | H26: 0 | I26: 0 | J26: 0 | K26: 0 | L26: 2 | M26: 3 | N26: 8 | O26: 6 | P26: 7 | Q26: 6 | R26: 6 | S26: 6 | T26: 10 | U26: 9 | V26: 5
B27: Precision | C27: 0 | D27: 0 | E27: 0 | F27: 0 | G27: 0 | H27: 0 | I27: 0 | J27: 0 | K27: 0 | L27: 0 | M27: 0.017857143 | N27: 0.080357143 | O27: 0.10714286 | P27: 0.11607143 | Q27: 0.10714286 | R27: 0.10714286 | S27: 0.10714286 | T27: 0.098214286 | U27: 0.125 | V27: 0.098214286
B28: Recall | C28: NaN | D28: NaN | E28: NaN | F28: NaN | G28: NaN | H28: NaN | I28: NaN | J28: NaN | K28: NaN | L28: 0 | M28: 0.4 | N28: 0.52941176 | O28: 0.66666667 | P28: 0.65 | Q28: 0.66666667 | R28: 0.66666667 | S28: 0.66666667 | T28: 0.52380952 | U28: 0.60869565 | V28: 0.6875
B29: F1 | C29: 0 | D29: 0 | E29: 0 | F29: 0 | G29: 0 | H29: 0 | I29: 0 | J29: 0 | K29: 0 | L29: 0 | M29: 0.034188034 | N29: 0.13953488 | O29: 0.18461538 | P29: 0.1969697 | Q29: 0.18461538 | R29: 0.18461538 | S29: 0.18461538 | T29: 0.16541353 | U29: 0.20740741 | V29: 0.171875
B30: Accuracy | C30: 0.9961919 | D30: 0.9961919 | E30: 0.9961919 | F30: 0.9961919 | G30: 0.9961919 | H30: 0.9961919 | I30: 0.9961919 | J30: 0.9961919 | K30: 0.9961919 | L30: 0.9961239 | M30: 0.9961579 | N30: 0.9962259 | O30: 0.99639591 | P30: 0.99639591 | Q30: 0.99639591 | R30: 0.99639591 | S30: 0.99639591 | T30: 0.9962259 | U30: 0.99636191 | V30: 0.99639591
A33: exhibition | B33: True Positive | C33: 0 | D33: 0 | E33: 0 | F33: 0 | G33: 0 | H33: 0 | I33: 0 | J33: 0 | K33: 0 | L33: 0 | M33: 0 | N33: 3 | O33: 27 | P33: 18 | Q33: 27 | R33: 27 | S33: 27 | T33: 22 | U33: 21 | V33: 28
B34: True Negative | C34: 29274 | D34: 29274 | E34: 29274 | F34: 29274 | G34: 29274 | H34: 29274 | I34: 29274 | J34: 29274 | K34: 29272 | L34: 29267 | M34: 29261 | N34: 29232 | O34: 29157 | P34: 29204 | Q34: 29157 | R34: 29194 | S34: 29176 | T34: 29144 | U34: 29175 | V34: 29174
B35: False Positive | C35: 137 | D35: 137 | E35: 137 | F35: 137 | G35: 137 | H35: 137 | I35: 137 | J35: 137 | K35: 137 | L35: 137 | M35: 137 | N35: 134 | O35: 110 | P35: 119 | Q35: 110 | R35: 110 | S35: 110 | T35: 115 | U35: 116 | V35: 109
B36: False Negative | C36: 0 | D36: 0 | E36: 0 | F36: 0 | G36: 0 | H36: 0 | I36: 0 | J36: 0 | K36: 2 | L36: 7 | M36: 13 | N36: 42 | O36: 117 | P36: 70 | Q36: 117 | R36: 80 | S36: 98 | T36: 130 | U36: 99 | V36: 100
B37: Precision | C37: 0 | D37: 0 | E37: 0 | F37: 0 | G37: 0 | H37: 0 | I37: 0 | J37: 0 | K37: 0 | L37: 0 | M37: 0 | N37: 0.02189781 | O37: 0.19708029 | P37: 0.13138686 | Q37: 0.19708029 | R37: 0.19708029 | S37: 0.19708029 | T37: 0.16058394 | U37: 0.15328467 | V37: 0.20437956
B38: Recall | C38: NaN | D38: NaN | E38: NaN | F38: NaN | G38: NaN | H38: NaN | I38: NaN | J38: NaN | K38: 0 | L38: 0 | M38: 0 | N38: 0.066666667 | O38: 0.1875 | P38: 0.20454545 | Q38: 0.1875 | R38: 0.25233645 | S38: 0.216 | T38: 0.14473684 | U38: 0.175 | V38: 0.21875
B39: F1 | C39: 0 | D39: 0 | E39: 0 | F39: 0 | G39: 0 | H39: 0 | I39: 0 | J39: 0 | K39: 0 | L39: 0 | M39: 0 | N39: 0.032967033 | O39: 0.19217082 | P39: 0.16 | Q39: 0.19217082 | R39: 0.22131148 | S39: 0.20610687 | T39: 0.15224913 | U39: 0.16342412 | V39: 0.21132075
B40: Accuracy | C40: 0.99534188 | D40: 0.99534188 | E40: 0.99534188 | F40: 0.99534188 | G40: 0.99534188 | H40: 0.99534188 | I40: 0.99534188 | J40: 0.99534188 | K40: 0.99527388 | L40: 0.99510387 | M40: 0.99489987 | N40: 0.99401584 | O40: 0.9922818 | P40: 0.99357383 | Q40: 0.9922818 | R40: 0.99353983 | S40: 0.99292782 | T40: 0.99166978 | U40: 0.99268981 | V40: 0.99289382
A43: fashion | B43: True Positive | C43: 0 | D43: 0 | E43: 0 | F43: 0 | G43: 0 | H43: 0 | I43: 0 | J43: 0 | K43: 0 | L43: 1 | M43: 3 | N43: 5 | O43: 3 | P43: 3 | Q43: 3 | R43: 3 | S43: 3 | T43: 1 | U43: 1 | V43: 3
B44: True Negative | C44: 29383 | D44: 29383 | E44: 29383 | F44: 29383 | G44: 29383 | H44: 29383 | I44: 29383 | J44: 29383 | K44: 29383 | L44: 29383 | M44: 29383 | N44: 29383 | O44: 29380 | P44: 29383 | Q44: 29380 | R44: 29383 | S44: 29382 | T44: 29382 | U44: 29383 | V44: 29382
B45: False Positive | C45: 28 | D45: 28 | E45: 28 | F45: 28 | G45: 28 | H45: 28 | I45: 28 | J45: 28 | K45: 28 | L45: 27 | M45: 25 | N45: 23 | O45: 25 | P45: 25 | Q45: 25 | R45: 25 | S45: 25 | T45: 27 | U45: 27 | V45: 25
B46: False Negative | C46: 0 | D46: 0 | E46: 0 | F46: 0 | G46: 0 | H46: 0 | I46: 0 | J46: 0 | K46: 0 | L46: 0 | M46: 0 | N46: 0 | O46: 3 | P46: 0 | Q46: 3 | R46: 0 | S46: 1 | T46: 1 | U46: 0 | V46: 1
B47: Precision | C47: 0.02 | D47: 0 | E47: 0 | F47: 0 | G47: 0 | H47: 0 | I47: 0 | J47: 0 | K47: 0 | L47: 0.035714286 | M47: 0.10714286 | N47: 0.17857143 | O47: 0.10714286 | P47: 0.10714286 | Q47: 0.10714286 | R47: 0.10714286 | S47: 0.10714286 | T47: 0.035714286 | U47: 0.035714286 | V47: 0.10714286
B48: Recall | C48: NaN | D48: NaN | E48: NaN | F48: NaN | G48: NaN | H48: NaN | I48: NaN | J48: NaN | K48: NaN | L48: 1 | M48: 1 | N48: 1 | O48: 0.5 | P48: 1 | Q48: 0.5 | R48: 1 | S48: 0.75 | T48: 0.5 | U48: 1 | V48: 0.75
...
